Workbook

Sheet Feuil12
A1: Country | B1: Terres_ag | C1: Superf_urbaine | D1: Retr_eau | E1: Stress_hydrique | F1: CO2_hab | G1: Elect_renouv | H1: Accès_élect | I1: Hauteur_précip | J1: PIB_hab
A2: Angola | B2: 36.8107804604155 | C2: 2991.3469865533 | D2: 0.7057 | E2: 1.8718833 | F2: 0.59274297 | G2: 53.174928 | H2: 48.223854 | I2: 1010 | J2: 3000.4442
A3: Albanie | B3: 42.538503649635 | C3: 827.69395654173 | D3: 0.786 | E3: 4.7235577 | F3: 1.5445501 | G3: 100 | H3: 100 | I3: 1485 | J3: 6810.114
A4: Émirats arabes unis | B4: 5.48859476203886 | C4: 2263.10504571 | D4: 2.381 | E4: 1587.3333 | F4: 20.252272 | G4: 0.23240111 | H4: 100 | I4: 78 | J4: 53707.98
A5: Arménie | B5: 58.8689848963822 | C5: 922.33502653 | D5: 2.83 | E5: 57.090982 | F5: 2.4046838 | G5: 28.336966 | H5: 100 | I5: 562 | J5: 7018.0515
A6: Australie | B6: 46.2524798427461 | C6: 11945.986036946 | D6: 8.64 | E6: 3.4740651 | F6: 14.776137 | G6: 13.637841 | H6: 100 | I6: 534 | J6: 65099.846
A7: Autriche | B7: 31.5398133785749 | C7: 2973.712010219 | D7: 3.49 | E7: 9.6435479 | F7: 6.6326457 | G7: 76.490779 | H7: 100 | I7: 1110 | J7: 52084.681
A8: Burundi | B8: 80.8411214953271 | C8: 887.842343383 | D8: 0.2801 | E8: 10.192868 | F8: 0.058384022 | G8: 82.709385 | H8: 10.233828 | I8: 1274 | J8: 259.02503
A9: Belgique | B9: 45.066357331572 | C9: 7730.879239745 | D9: 4.199 | E9: 51.584767 | F9: 7.3981307 | G9: 20.800023 | H9: 100 | I9: 847 | J9: 49926.825
A10: Bénin | B10: 35.0301525363604 | C10: 2005.9093441513 | D10: 0.13 | E10: 0.97524381 | F10: 0.63120481 | G10: 5.5555556 | H10: 41.973633 | I10: 1039 | J10: 1302.851
A11: Burkina Faso | B11: 46.1038011695906 | C11: 1599.295141703 | D11: 0.818 | E11: 7.8202677 | F11: 0.25353319 | G11: 9.3540387 | H11: 18.950687 | I11: 748 | J11: 830.03715
A12: Bangladesh | B12: 76.2694937389568 | C12: 56970.02069378 | D12: 35.87 | E12: 5.7233395 | F12: 0.51064756 | G12: 1.2268899 | H12: 98.991028 | I12: 2666 | J12: 2688.3055
A13: Bulgarie | B13: 46.4904200442152 | C13: 2109.34419338666 | D13: 5.076 | E13: 37.519403 | F13: 4.9232804 | G13: 17.988593 | H13: 99.8 | I13: 608 | J13: 13974.449
... A120: Zimbabwe | B120: 41.8766963939511 | C120: 2024.485896677 | D120: 3.7713817 | E120: 35.405385 | F120: 0.53048355 | G120: 52.724276 | H120: 48.979927 | I120: 657 | J120: 1676.8215

Sheet Feuil13
A1: Last Updated Date | B1: 45343 | C1: 2020 | D1: 2020 | E1: 2015 | F1: 2020 | G1: 2020 | H1: 2020 | I1: 2015 | J1: 2021 | K1: 2020 | L1: 2022
C2: Terres-ag | D2: CO2 | E2: Superf-urbaine | F2: Retr_eau | G2: Stress_hydrique | H2: CO2_hab | I2: Elect_renouv | J2: Accès_élect | K2: Hauteur_précip | L2: PIB_hab
A3: Country Name | B3: Country Code
A4: Angola | B4: AGO | C4: 36.8107804604155 | D4: 0.24342379 | E4: 2991.3469865533 | F4: 0.7057 | G4: 1.8718833 | H4: 0.59274297 | I4: 53.174928 | J4: 48.223854 | K4: 1010 | L4: 3000.4442
A5: Albanie | B5: ALB | C5: 42.538503649635 | D5: 0.34955163 | E5: 827.69395654173 | F5: 0.786 | G5: 4.7235577 | H5: 1.5445501 | I5: 100 | J5: 100 | K5: 1485 | L5: 6810.114
A6: Émirats arabes unis | B6: ARE | C6: 5.48859476203886 | D6: 0.49065424 | E6: 2263.10504571 | F6: 2.381 | G6: 1587.3333 | H6: 20.252272 | I6: 0.23240111 | J6: 100 | K6: 78 | L6: 53707.98
A7: Argentine | B7: ARG | C7: 43.0292651706989 | D7: 0.30014294 | E7: 11432.7305610191 | F7: 37.69 | G7: 10.456664 | H7: 3.4056175 | I7: 28.140069 | J7: 100 | K7: 591 | L7: 13650.605
A8: Arménie | B8: ARM | C8: 58.8689848963822 | D8: 0.56499286 | E8: 922.33502653 | F8: 2.83 | G8: 57.090982 | H8: 2.4046838 | I8: 28.336966 | J8: 100 | K8: 562 | L8: 7018.0515
A9: Australie | B9: AUS | C9: 46.2524798427461 | D9: 0.25439944 | E9: 11945.986036946 | F9: 8.64 | G9: 3.4740651 | H9: 14.776137 | I9: 13.637841 | J9: 100 | K9: 534 | L9: 65099.846
A10: Autriche | B10: AUT | C10: 31.5398133785749 | D10: 0.15302349 | E10: 2973.712010219 | F10: 3.49 | G10: 9.6435479 | H10: 6.6326457 | I10: 76.490779 | J10: 100 | K10: 1110 | L10: 52084.681
A11: Azerbaïdjan | B11: AZE | C11: 57.8382498850519 | D11: 0.6685963 | E11: 2589.858867181 | F11: 12.59 | G11: 55.597262 | H11: 3.3988496 | I11: 7.0398574 | J11: 100 | K11: 447 | L11: 7762.0738
A12: Burundi | B12: BDI | C12: 80.8411214953271 | D12: 0.22168819 | E12: 887.842343383 | F12: 0.2801 | G12: 10.192868 | H12: 0.058384022 | I12: 82.709385 | J12: 10.233828 | K12: 1274 | L12: 259.02503
A13: Belgique | B13: BEL | C13: 45.066357331572 | D13: 0.18197096 | E13: 7730.879239745 | F13: 4.199 | G13: 51.584767 | H13: 7.3981307 | I13: 20.800023 | J13: 100 | K13: 847 | L13: 49926.825
A14: Bénin | B14: BEN | C14: 35.0301525363604 | D14: 0.54194209 | E14: 2005.9093441513 | F14: 0.13 | G14: 0.97524381 | H14: 0.63120481 | I14: 5.5555556 | J14: 41.973633 | K14: 1039 | L14: 1302.851
A15: Burkina Faso | B15: BFA | C15: 46.1038011695906 | D15: 0.35756353 | E15: 1599.295141703 | F15: 0.818 | G15: 7.8202677 | H15: 0.25353319 | I15: 9.3540387 | J15: 18.950687 | K15: 748 | L15: 830.03715
... A157: Zimbabwe | B157: ZWE | C157: 41.8766963939511 | D157: 0.43728966 | E157: 2024.485896677 | F157: 3.7713817 | G157: 35.405385 | H157: 0.53048355 | I157: 52.724276 | J157: 48.979927 | K157: 657 | L157: 1676.8215

Sheet Data
A1: Data Source | B1: Indicateurs du développement dans le monde
A2: Last Updated Date | B2: 45343
A4: Country Name | B4: Country Code | C4: Indicator Name | D4: Indicator Code | E4: 1960 | F4: 1961 | G4: 1962 | H4: 1963 | I4: 1964 | J4: 1965 | K4: 1966 | L4: 1967 | M4: 1968 | N4: 1969 | O4: 1970 | P4: 1971 | Q4: 1972 | R4: 1973 | S4: 1974 | T4: 1975 | U4: 1976 | V4: 1977 | W4: 1978 | X4: 1979 | Y4: 1980 | Z4: 1981 | AA4: 1982 | AB4: 1983 | AC4: 1984 | AD4: 1985 | AE4: 1986 | AF4: 1987 | AG4: 1988 | AH4: 1989 | AI4: 1990 | AJ4: 1991 | AK4: 1992 | AL4: 1993 | AM4: 1994 | AN4: 1995 | AO4: 1996 | AP4: 1997 | AQ4: 1998 | AR4: 1999 | AS4: 2000 | AT4: 2001 | AU4: 2002 | AV4: 2003 | AW4: 2004 | AX4: 2005 | AY4: 2006 | AZ4: 2007 | BA4: 2008 | BB4: 2009 | BC4: 2010 | BD4: 2011 | BE4: 2012 | BF4: 2013 | BG4: 2014 | BH4: 2015 | BI4: 2016 | BJ4: 2017 | BK4: 2018 | BL4: 2019 | BM4: 2020 | BN4: 2021 | BO4: 2022
A5: Aruba | B5: ABW | C5: Émissions de CO2 (kg par $ US de 2010 de PIB) | D5: EN.ATM.CO2E.KD.GD
B6: AFE | C6: Émissions de CO2 (kg par $ US de 2010 de PIB) | D6: EN.ATM.CO2E.KD.GD | AI6: 0.73671476 | AJ6: 0.72487138 | AK6: 0.73153475 | AL6: 0.75549239 | AM6: 0.7634418 | AN6: 0.76691019 | AO6: 0.75493622 | AP6: 0.75640828 | AQ6: 0.7620796 | AR6: 0.71314379 | AS6: 0.69940481 | AT6: 0.74479504 | AU6: 0.73736731 | AV6: 0.7541225 | AW6: 0.76649265 | AX6: 0.72393554 | AY6: 0.68956872 | AZ6: 0.67587707 | BA6: 0.69230369 | BB6: 0.66450716 | BC6: 0.66688074 | BD6: 0.63428974 | BE6: 0.65440411 | BF6: 0.65292984 | BG6: 0.65331462 | BH6: 0.61797069 | BI6: 0.60870283 | BJ6: 0.60436964 | BK6: 0.5974779 | BL6: 0.59726758 | BM6: 0.54829262
A7: Afghanistan | B7: AFG | C7: Émissions de CO2 (kg par $ US de 2010 de PIB) | D7: EN.ATM.CO2E.KD.GD | AU7: 0.19408903 | AV7: 0.21013749 | AW7: 0.16197336 | AX7: 0.2210508 | AY7: 0.24424589 | AZ7: 0.26758412 | BA7: 0.39561335 | BB7: 0.48851758 | BC7: 0.558539 | BD7: 0.77573474 | BE7: 0.58713 | BF7: 0.51208688 | BG7: 0.49210475 | BH7: 0.52563361 | BI7: 0.47503783 | BJ7: 0.49902695 | BK7: 0.53988636 | BL7: 0.53218003 | BM7: 0.42233964
B8: AFW | C8: Émissions de CO2 (kg par $ US de 2010 de PIB) | D8: EN.ATM.CO2E.KD.GD | AI8: 0.37351733 | AJ8: 0.42023503 | AK8: 0.45019448 | AL8: 0.43084273 | AM8: 0.39896554 | AN8: 0.42826162 | AO8: 0.47286224 | AP8: 0.45377827 | AQ8: 0.42262827 | AR8: 0.42477443 | AS8: 0.4364687 | AT8: 0.4361945 | AU8: 0.37208574 | AV8: 0.37679857 | AW8: 0.35258533 | AX8: 0.33827349 | AY8: 0.30460451 | AZ8: 0.27979877 | BA8: 0.27715248 | BB8: 0.25150004 | BC8: 0.26424212 | BD8: 0.26137892 | BE8: 0.25589805 | BF8: 0.26401391 | BG8: 0.26241713 | BH8: 0.25266208 | BI8: 0.26143647 | BJ8: 0.25451634 | BK8: 0.25991494 | BL8: 0.26664683 | BM8: 0.26063217
A9: Angola | B9: AGO | C9: Émissions de CO2 (kg par $ US de 2010 de PIB) | D9: EN.ATM.CO2E.KD.GD | AI9: 0.23720778 | AJ9: 0.23882602 | AK9: 0.26134036 | AL9: 0.46338915 | AM9: 0.55733 | AN9: 0.54559895 | AO9: 0.58338245 | AP9: 0.56891481 | AQ9: 0.56404231 | AR9: 0.57982847 | AS9: 0.51763045 | AT9: 0.48912727 | AU9: 0.42313631 | AV9: 0.43901009 | AW9: 0.41193988 | AX9: 0.3244162 | AY9: 0.30457324 | AZ9: 0.27372526 | BA9: 0.27972979 | BB9: 0.304247 | BC9: 0.31425941 | BD9: 0.31789068 | BE9: 0.29290014 | BF9: 0.31521071 | BG9: 0.33028816 | BH9: 0.34972543 | BI9: 0.33484793 | BJ9: 0.28472444 | BK9: 0.27209155 | BL9: 0.28265808 | BM9: 0.24342379
A10: Albanie | B10: ALB | C10: Émissions de CO2 (kg par $ US de 2010 de PIB) | D10: EN.ATM.CO2E.KD.GD | AI10: 1.1480044 | AJ10: 1.0838535 | AK10: 0.63477457 | AL10: 0.53775775 | AM10: 0.49803649 | AN10: 0.41132169 | AO10: 0.38027908 | AP10: 0.32085751 | AQ10: 0.35968278 | AR10: 0.5270932 | AS10: 0.52607312 | AT10: 0.49305114 | AU10: 0.54861072 | AV10: 0.57176059 | AW10: 0.5660943 | AX10: 0.50834902 | AY10: 0.47836292 | AZ10: 0.47088512 | BA10: 0.43300249 | BB10: 0.43474429 | BC10: 0.45924222 | BD10: 0.4807193 | BE10: 0.41910569 | BF10: 0.43811724 | BG10: 0.46572196 | BH10: 0.4212753 | BI10: 0.38873458 | BJ10: 0.44250276 | BK10: 0.41850802 | BL10: 0.38505683 | BM10: 0.34955163
A11: Andorre | B11: AND | C11: Émissions de CO2 (kg par $ US de 2010 de PIB) | D11: EN.ATM.CO2E.KD.GD | AI11: 0.24828745 | AJ11: 0.24212299 | AK11: 0.23989386 | AL11: 0.24457785 | AM11: 0.23675189 | AN11: 0.24077696 | AO11: 0.24594641 | AP11: 0.23095452 | AQ11: 0.23614011 | AR11: 0.23699878 | AS11: 0.23382706 | AT11: 0.21626753 | AU11: 0.20975598 | AV11: 0.19430896 | AW11: 0.18830524 | AX11: 0.18333234 | AY11: 0.16600777 | AZ11: 0.16127458 | BA11: 0.17076789 | BB11: 0.17297011 | BC11: 0.17645502 | BD11: 0.16770838 | BE11: 0.17517058 | BF11: 0.17751695 | BG11: 0.16785112 | BH11: 0.16679125 | BI11: 0.16209149 | BJ11: 0.1602705 | BK11: 0.16770189 | BL11: 0.15951779 | BM11: 0.16796754
A12: Le monde arabe | B12: ARB | C12: Émissions de CO2 (kg par $ US de 2010 de PIB) | D12: EN.ATM.CO2E.KD.GD | AI12: 0.65540391 | AJ12: 0.64210023 | AK12: 0.66294637 | AL12: 0.69213083 | AM12: 0.70987173 | AN12: 0.71003045 | AO12: 0.70188705 | AP12: 0.70283206 | AQ12: 0.67239226 | AR12: 0.66901208 | AS12: 0.65389339 | AT12: 0.67814198 | AU12: 0.69618173 | AV12: 0.6837005 | AW12: 0.66203221 | AX12: 0.67040048 | AY12: 0.66534172 | AZ12: 0.66250026 | BA12: 0.6784182 | BB12: 0.69856866 | BC12: 0.70681311 | BD12: 0.69838813 | BE12: 0.71225914 | BF12: 0.70762876 | BG12: 0.71500764 | BH12: 0.70785775 | BI12: 0.68965182 | BJ12: 0.68703959 | BK12: 0.66454477 | BL12: 0.66262786 | BM12: 0.66731218
A13: Émirats arabes unis | B13: ARE | C13: Émissions de CO2 (kg par $ US de 2010 de PIB) | D13: EN.ATM.CO2E.KD.GD | AI13: 0.43424485 | AJ13: 0.48008927 | AK13: 0.45050533 | AL13: 0.47408611 | AM13: 0.49341034 | AN13: 0.49114589 | AO13: 0.48498925 | AP13: 0.46490023 | AQ13: 0.47497985 | AR13: 0.47391958 | AS13: 0.42277813 | AT13: 0.47829573 | AU13: 0.47629998 | AV13: 0.45841214 | AW13: 0.44332084 | AX13: 0.44756876 | AY13: 0.4253588 | AZ13: 0.44705538 | BA13: 0.51279602 | BB13: 0.54455183 | BC13: 0.55565304 | BD13: 0.53548286 | BE13: 0.55447008 | BF13: 0.55564437 | BG13: 0.53826579 | BH13: 0.5277406 | BI13: 0.51270082 | BJ13: 0.48746455 | BK13: 0.43673553 | BL13: 0.46027527 | BM13: 0.49065424
A14: Argentine | B14: ARG | C14: Émissions de CO2 (kg par $ US de 2010 de PIB) | D14: EN.ATM.CO2E.KD.GD | AI14: 0.37737925 | AJ14: 0.36507609 | AK14: 0.34466344 | AL14: 0.32541516 | AM14: 0.31208137 | AN14: 0.32402454 | AO14: 0.33332784 | AP14: 0.31730887 | AQ14: 0.32141629 | AR14: 0.33727311 | AS14: 0.33430258 | AT14: 0.3311854 | AU14: 0.34855281 | AV14: 0.34803813 | AW14: 0.35353036 | AX14: 0.33539293 | AY14: 0.32938354 | AZ14: 0.31757969 | BA14: 0.31346642 | BB14: 0.31193899 | BC14: 0.30254162 | BD14: 0.30147513 | BE14: 0.30686697 | BF14: 0.30858455 | BG14: 0.31022464 | BH14: 0.3119802 | BI14: 0.31450219 | BJ14: 0.29938216 | BK14: 0.30335981 | BL14: 0.29427209 | BM14: 0.30014294
A15: Arménie | B15: ARM | C15: Émissions de CO2 (kg par $ US de 2010 de PIB) | D15: EN.ATM.CO2E.KD.GD | AI15: 3.3982804 | AJ15: 4.0123158 | AK15: 3.5840102 | AL15: 1.8174973 | AM15: 0.93866883 | AN15: 1.1144385 | AO15: 0.76021927 | AP15: 0.98551699 | AQ15: 0.96494065 | AR15: 0.82993798 | AS15: 0.89937307 | AT15: 0.83004389 | AU15: 0.63486959 | AV15: 0.62417009 | AW15: 0.60823349 | AX15: 0.63291087 | AY15: 0.56265554 | AZ15: 0.57369867 | BA15: 0.58627873 | BB15: 0.54149678 | BC15: 0.5093787 | BD15: 0.55388124 | BE15: 0.59824648 | BF15: 0.55735351 | BG15: 0.53578576 | BH15: 0.50632324 | BI15: 0.47914575 | BJ15: 0.4725126 | BK15: 0.47766305 | BL15: 0.4814923 | BM15: 0.56499286
A16: Samoa américaines | B16: ASM | C16: Émissions de CO2 (kg par $ US de 2010 de PIB) | D16: EN.ATM.CO2E.KD.GD
A17: Antigua-et-Barbuda | B17: ATG | C17: Émissions de CO2 (kg par $ US de 2010 de PIB) | D17: EN.ATM.CO2E.KD.GD | AI17: 0.26072638 | AJ17: 0.25891457 | AK17: 0.25259691 | AL17: 0.24377221 | AM17: 0.23180885 | AN17: 0.25313809 | AO17: 0.25724339 | AP17: 0.25615058 | AQ17: 0.26139634 | AR17: 0.26377251 | AS17: 0.25931897 | AT17: 0.27984672 | AU17: 0.28835954 | AV17: 0.29260832 | AW17: 0.28179247 | AX17: 0.27135821 | AY17: 0.25437539 | AZ17: 0.24509363 | BA17: 0.25033309 | BB17: 0.30128628 | BC17: 0.33571143 | BD17: 0.33528742 | BE17: 0.3405309 | BF17: 0.3410477 | BG17: 0.33627942 | BH17: 0.34094808 | BI17: 0.33440232 | BJ17: 0.32610208 | BK17: 0.31008399 | BL17: 0.30099566 | BM17: 0.34597473
A18: Australie | B18: AUS | C18: Émissions de CO2 (kg par $ US de 2010 de PIB) | D18: EN.ATM.CO2E.KD.GD | AI18: 0.41849642 | AJ18: 0.42212944 | AK18: 0.42613839 | AL18: 0.41666788 | AM18: 0.41111117 | AN18: 0.4099365 | AO18: 0.40834223 | AP18: 0.40291141 | AQ18: 0.40967296 | AR18: 0.39737507 | AS18: 0.3889636 | AT18: 0.38819179 | AU18: 0.38165906 | AV18: 0.36977432 | AW18: 0.36810616 | AX18: 0.35944339 | AY18: 0.35483458 | AZ18: 0.35131337 | BA18: 0.34197596 | BB18: 0.34107046 | BC18: 0.3354491 | BD18: 0.32627081 | BE18: 0.31496586 | BF18: 0.30133159 | BG18: 0.28674867 | BH18: 0.28539078 | BI18: 0.284167 | BJ18: 0.27937748 | BK18: 0.27074231 | BL18: 0.2643873 | BM18: 0.25439944
A19: Autriche | B19: AUT | C19: Émissions de CO2 (kg par $ US de 2010 de PIB) | D19: EN.ATM.CO2E.KD.GD | AI19: 0.24218065 | AJ19: 0.25078562 | AK19: 0.22693072 | AL19: 0.22627386 | AM19: 0.22281694 | AN19: 0.22781768 | AO19: 0.23610803 | AP19: 0.2288475 | AQ19: 0.22247947 | AR19: 0.20946421 | AS19: 0.20417788 | AT19: 0.21550842 | AU19: 0.21656404 | AV19: 0.23029676 | AW19: 0.22818182 | AX19: 0.22446997 | AY19: 0.21089108 | AZ19: 0.19547596 | BA19: 0.19127425 | BB19: 0.18101496 | BC19: 0.19304764 | BD19: 0.18303727 | BE19: 0.17337536 | BF19: 0.17503672 | BG19: 0.16410675 | BH19: 0.16560073 | BI19: 0.16350608 | BJ19: 0.16534346 | BK19: 0.15472209 | BL19: 0.15581078 | BM19: 0.15302349
A20: Azerbaïdjan | B20: AZE | C20: Émissions de CO2 (kg par $ US de 2010 de PIB) | D20: EN.ATM.CO2E.KD.GD | AI20: 2.6424633 | AJ20: 2.5902246 | AK20: 4.0892584 | AL20: 4.0168206 | AM20: 3.4889805 | AN20: 3.8329633 | AO20: 3.1683949 | AP20: 2.9172062 | AQ20: 2.6520957 | AR20: 2.4350311 | AS20: 2.3230563 | AT20: 2.0153054 | AU20: 1.8261694 | AV20: 1.8084148 | AW20: 1.640323 | AX20: 1.3602853 | AY20: 1.0263447 | AZ20: 0.74403497 | BA20: 0.74032556 | BB20: 0.56719528 | BC20: 0.51486239 | BD20: 0.57718627 | BE20: 0.62352582 | BF20: 0.6055135 | BG20: 0.61413804 | BH20: 0.59863515 | BI20: 0.62684918 | BJ20: 0.62011808 | BK20: 0.62569566 | BL20: 0.66252713 | BM20: 0.6685963
A21: Burundi | B21: BDI | C21: Émissions de CO2 (kg par $ US de 2010 de PIB) | D21: EN.ATM.CO2E.KD.GD | AI21: 0.07863062 | AJ21: 0.091654657 | AK21: 0.079514488 | AL21: 0.088768536 | AM21: 0.092303771 | AN21: 0.10324174 | AO21: 0.1155305 | AP21: 0.11892175 | AQ21: 0.11669107 | AR21: 0.1185408 | AS21: 0.13429363 | AT21: 0.10533087 | AU21: 0.10463685 | AV21: 0.083153423 | AW21: 0.07394495 | AX21: 0.073928236 | AY21: 0.083460787 | AZ21: 0.080886428 | BA21: 0.07978646 | BB21: 0.076624055 | BC21: 0.11895531 | BD21: 0.12707669 | BE21: 0.12332578 | BF21: 0.11824799 | BG21: 0.11294214 | BH21: 0.11816997 | BI21: 0.14325628 | BJ21: 0.17063303 | BK21: 0.21103063 | BL21: 0.22052247 | BM21: 0.22168819
A22: Belgique | B22: BEL | C22: Émissions de CO2 (kg par $ US de 2010 de PIB) | D22: EN.ATM.CO2E.KD.GD | AI22: 0.37250056 | AJ22: 0.38134729 | AK22: 0.37022327 | AL22: 0.3664277 | AM22: 0.37042507 | AN22: 0.3607495 | AO22: 0.37120916 | AP22: 0.34921695 | AQ22: 0.35065569 | AR22: 0.32760222 | AS22: 0.32067544 | AT22: 0.32006858 | AU22: 0.29478022 | AV22: 0.30399545 | AW22: 0.28804661 | AX22: 0.27557353 | AY22: 0.26174357 | AZ22: 0.24270712 | BA22: 0.24816079 | BB22: 0.23711364 | BC22: 0.24658944 | BD22: 0.21891925 | BE22: 0.2145818 | BF22: 0.21645931 | BG22: 0.19943763 | BH22: 0.2056861 | BI22: 0.20113888 | BJ22: 0.19460347 | BK22: 0.19310805 | BL22: 0.18779761 | BM22: 0.18197096
A23: Bénin | B23: BEN | C23: Émissions de CO2 (kg par $ US de 2010 de PIB) | D23: EN.ATM.CO2E.KD.GD | AI23: 0.083397851 | AJ23: 0.066297042 | AK23: 0.066534912 | AL23: 0.063907003 | AM23: 0.061126001 | AN23: 0.062109424 | AO23: 0.1918651 | AP23: 0.23049164 | AQ23: 0.21779381 | AR23: 0.22816238 | AS23: 0.22904307 | AT23: 0.26485867 | AU23: 0.31761255 | AV23: 0.34453621 | AW23: 0.35736118 | AX23: 0.38495752 | AY23: 0.44338505 | AZ23: 0.48182682 | BA23: 0.4615639 | BB23: 0.49596916 | BC23: 0.5305525 | BD23: 0.49685927 | BE23: 0.45286874 | BF23: 0.44450993 | BG23: 0.46349158 | BH23: 0.48344944 | BI23: 0.57263089 | BJ23: 0.55292941 | BK23: 0.57307315 | BL23: 0.52719334 | BM23: 0.54194209
A24: Burkina Faso | B24: BFA | C24: Émissions de CO2 (kg par $ US de 2010 de PIB) | D24: EN.ATM.CO2E.KD.GD | AI24: 0.19527924 | AJ24: 0.18069781 | AK24: 0.18364572 | AL24: 0.18122145 | AM24: 0.17950034 | AN24: 0.17357109 | AO24: 0.17716785 | AP24: 0.19030773 | AQ24: 0.18837391 | AR24: 0.1861881 | AS24: 0.20535734 | AT24: 0.18808294 | AU24: 0.18076519 | AV24: 0.1799654 | AW24: 0.1771509 | AX24: 0.16553854 | AY24: 0.18951755 | AZ24: 0.21873183 | BA24: 0.23460166 | BB24: 0.23029883 | BC24: 0.23042848 | BD24: 0.22706478 | BE24: 0.26105254 | BF24: 0.27003277 | BG24: 0.26322492 | BH24: 0.32131075 | BI24: 0.31887715 | BJ24: 0.34737141 | BK24: 0.36266109 | BL24: 0.37711201 | BM24: 0.35756353
A25: Bangladesh | B25: BGD | C25: Émissions de CO2 (kg par $ US de 2010 de PIB) | D25: EN.ATM.CO2E.KD.GD | AI25: 0.2181121 | AJ25: 0.19809215 | AK25: 0.20508655 | AL25: 0.20819832 | AM25: 0.21594953 | AN25: 0.25110067 | AO25: 0.24416511 | AP25: 0.26347197 | AQ25: 0.25418215 | AR25: 0.25363992 | AS25: 0.24785246 | AT25: 0.29229273 | AU25: 0.29961839 | AV25: 0.30016827 | AW25: 0.30412967 | AX25: 0.30588808 | AY25: 0.31473834 | AZ25: 0.31109667 | BA25: 0.32116652 | BB25: 0.32904444 | BC25: 0.35164008 | BD25: 0.35529436 | BE25: 0.36225573 | BF25: 0.36476624 | BG25: 0.36220461 | BH25: 0.37501248 | BI25: 0.38825932 | BJ25: 0.39356853 | BK25: 0.40139418 | BL25: 0.35927245 | BM25: 0.32048727
A26: Bulgarie | B26: BGR | C26: Émissions de CO2 (kg par $ US de 2010 de PIB) | D26: EN.ATM.CO2E.KD.GD | AI26: 1.9053537 | AJ26: 1.6632471 | AK26: 1.6881186 | AL26: 1.7308474 | AM26: 1.6330331 | AN26: 1.6218394 | AO26: 1.5533598 | AP26: 1.7332045 | AQ26: 1.5906118 | AR26: 1.5246554 | AS26: 1.4281523 | AT26: 1.4631329 | AU26: 1.3046135 | AV26: 1.3629019 | AW26: 1.261773 | AX26: 1.1965577 | AY26: 1.1429736 | AZ26: 1.1514291 | BA26: 1.0321364 | BB26: 0.91568773 | BC26: 0.94017804 | BD26: 1.0217276 | BE26: 0.9198559 | BF26: 0.81471993 | BG26: 0.85576684 | BH26: 0.87688939 | BI26: 0.79439906 | BJ26: 0.81589963 | BK26: 0.74041453 | BL26: 0.68144695 | BM26: 0.61859373
A27: Bahreïn | B27: BHR | C27: Émissions de CO2 (kg par $ US de 2010 de PIB) | D27: EN.ATM.CO2E.KD.GD | AI27: 1.1922406 | AJ27: 1.032845 | AK27: 1.1482618 | AL27: 1.0831488 | AM27: 1.1112777 | AN27: 1.0823578 | AO27: 1.0871793 | AP27: 1.0739916 | AQ27: 1.1011944 | AR27: 1.0532023 | AS27: 1.0277433 | AT27: 1.0349654 | AU27: 1.0524718 | AV27: 1.0316757 | AW27: 0.96345108 | AX27: 1.0416163 | AY27: 1.0630537 | AZ27: 1.0041465 | BA27: 1.0174921 | BB27: 0.99048181 | BC27: 0.99729105 | BD27: 0.97984897 | BE27: 0.98662523 | BF27: 0.99374838 | BG27: 0.9995073 | BH27: 0.98202168 | BI27: 0.94233142 | BJ27: 0.90993549 | BK27: 0.90074507 | BL27: 0.94230582 | BM27: 0.97331837
A28: Bahamas | B28: BHS | C28: Émissions de CO2 (kg par $ US de 2010 de PIB) | D28: EN.ATM.CO2E.KD.GD | AI28: 0.23558797 | AJ28: 0.25449822 | AK28: 0.24776941 | AL28: 0.23089184 | AM28: 0.22684806 | AN28: 0.22609729 | AO28: 0.21360913 | AP28: 0.18874326 | AQ28: 0.22116456 | AR28: 0.21105077 | AS28: 0.20149166 | AT28: 0.18883625 | AU28: 0.18696261 | AV28: 0.19367806 | AW28: 0.1900515 | AX28: 0.17160321 | AY28: 0.16319649 | AZ28: 0.16298797 | BA28: 0.17114127 | BB28: 0.18105953 | BC28: 0.17573233 | BD28: 0.19262693 | BE28: 0.20494653 | BF28: 0.2472122 | BG28: 0.21794019 | BH28: 0.18910468 | BI28: 0.17616785 | BJ28: 0.1827347 | BK28: 0.22870338 | BL28: 0.21618174 | BM28: 0.26465695
A29: Bosnie-Herzégovine | B29: BIH | C29: Émissions de CO2 (kg par $ US de 2010 de PIB) | D29: EN.ATM.CO2E.KD.GD | AM29: 1.2982844 | AN29: 1.1450136 | AO29: 0.75317226 | AP29: 1.1365278 | AQ29: 1.2456661 | AR29: 1.1107218 | AS29: 1.3070957 | AT29: 1.2586669 | AU29: 1.2674034 | AV29: 1.2466557 | AW29: 1.2277055 | AX29: 1.2312602 | AY29: 1.2893077 | AZ29: 1.2844982 | BA29: 1.3389591 | BB29: 1.3690304 | BC29: 1.3739455 | BD29: 1.5499591 | BE29: 1.4457483 | BF29: 1.4053253 | BG29: 1.2404314 | BH29: 1.1965729 | BI29: 1.3200466 | BJ29: 1.2977901 | BK29: 1.2457125 | BL29: 1.1309053 | BM29: 1.1562652
A30: Bélarus | B30: BLR | C30: Émissions de CO2 (kg par $ US de 2010 de PIB) | D30: EN.ATM.CO2E.KD.GD | AI30: 3.3895006 | AJ30: 3.3065348 | AK30: 3.335719 | AL30: 3.1353486 | AM30: 3.0120043 | AN30: 2.9904418 | AO30: 2.9568326 | AP30: 2.6799898 | AQ30: 2.396136 | AR30: 2.226438 | AS30: 2.0281696 | AT30: 1.8910515 | AU30: 1.8013635 | AV30: 1.7079734 | AW30: 1.6266716 | AX30: 1.5058699 | AY30: 1.425451 | AZ30: 1.2798149 | BA30: 1.2202034 | BB30: 1.1560139 | BC30: 1.1524046 | BD30: 1.0380911 | BE30: 1.0455904 | BF30: 1.0378521 | BG30: 1.0124147 | BH30: 0.97194948 | BI30: 1.0031341 | BJ30: 0.99689732 | BK30: 1.0184272 | BL30: 0.97697135 | BM30: 0.93448481
A31: Belize | B31: BLZ | C31: Émissions de CO2 (kg par $ US de 2010 de PIB) | D31: EN.ATM.CO2E.KD.GD | AI31: 0.45320933 | AJ31: 0.52614674 | AK31: 0.40424605 | AL31: 0.40396982 | AM31: 0.40106277 | AN31: 0.40062183 | AO31: 0.32329134 | AP31: 0.39309115 | AQ31: 0.36084305 | AR31: 0.30897215 | AS31: 0.31262717 | AT31: 0.33711406 | AU31: 0.29878369 | AV31: 0.27275364 | AW31: 0.23683389 | AX31: 0.24622953 | AY31: 0.24961856 | AZ31: 0.25757971 | BA31: 0.23994625 | BB31: 0.28438529 | BC31: 0.28047982 | BD31: 0.3036674 | BE31: 0.23771447 | BF31: 0.22374929 | BG31: 0.22750243 | BH31: 0.30760338 | BI31: 0.29679187 | BJ31: 0.2984675 | BK31: 0.2893335 | BL31: 0.32436595 | BM31: 0.35117536
A32: Bermudes | B32: BMU | C32: Émissions de CO2 (kg par $ US de 2010 de PIB) | D32: EN.ATM.CO2E.KD.GD
A33: Bolivie | B33: BOL | C33: Émissions de CO2 (kg par $ US de 2010 de PIB) | D33: EN.ATM.CO2E.KD.GD | AI33: 0.86917773 | AJ33: 0.86218571 | AK33: 0.87208692 | AL33: 0.7680241 | AM33: 0.6840383 | AN33: 0.58989685 | AO33: 0.54538952 | AP33: 0.5729807 | AQ33: 0.51836213 | AR33: 0.48993862 | AS33: 0.46773602 | AT33: 0.44324334 | AU33: 0.46164407 | AV33: 0.47851796 | AW33: 0.48540741 | AX33: 0.48965659 | AY33: 0.506573 | AZ33: 0.53838224 | BA33: 0.54241032 | BB33: 0.55925392 | BC33: 0.58188413 | BD33: 0.60161158 | BE33: 0.60698541 | BF33: 0.60732817 | BG33: 0.61891742 | BH33: 0.60614484 | BI33: 0.61988879 | BJ33: 0.60328432 | BK33: 0.5856075 | BL33: 0.57153584 | BM33: 0.52717829
A34: Brésil | B34: BRA | C34: Émissions de CO2 (kg par $ US de 2010 de PIB) | D34: EN.ATM.CO2E.KD.GD | AI34: 0.21575992 | AJ34: 0.22173322 | AK34: 0.22553942 | AL34: 0.22259986 | AM34: 0.21736272 | AN34: 0.22616282 | AO34: 0.2406532 | AP34: 0.24953378 | AQ34: 0.25687167 | AR34: 0.26480071 | AS34: 0.26438448 | AT34: 0.26550277 | AU34: 0.25632977 | AV34: 0.24789652 | AW34: 0.24775079 | AX34: 0.24238142 | AY34: 0.23591054 | AZ34: 0.23363041 | BA34: 0.23559612 | BB34: 0.22097273 | BC34: 0.23364416 | BD34: 0.2362129 | BE34: 0.25167187 | BF34: 0.26187195 | BG34: 0.2738175 | BH34: 0.26930463 | BI34: 0.25647325 | BJ34: 0.2579981 | BK34: 0.24132498 | BL34: 0.23867781 | BM34: 0.23529857
A35: Barbade | B35: BRB | C35: Émissions de CO2 (kg par $ US de 2010 de PIB) | D35: EN.ATM.CO2E.KD.GD | AI35: 0.25597825 | AJ35: 0.26522849 | AK35: 0.26034829 | AL35: 0.24465309 | AM35: 0.2542559 | AN35: 0.25379964 | AO35: 0.25282715 | AP35: 0.26306257 | AQ35: 0.26988399 | AR35: 0.28592097 | AS35: 0.26908143 | AT35: 0.28225814 | AU35: 0.27763636 | AV35: 0.28154615 | AW35: 0.28435739 | AX35: 0.28334508 | AY35: 0.2715239 | AZ35: 0.26982268 | BA35: 0.31749164 | BB35: 0.33034112 | BC35: 0.31304557 | BD35: 0.32280342 | BE35: 0.31340852 | BF35: 0.31144342 | BG35: 0.27739152 | BH35: 0.26818124 | BI35: 0.26591846 | BJ35: 0.24197255 | BK35: 0.26276008 | BL35: 0.24083831 | BM35: 0.25915961
A36: Brunéi Darussalam | B36: BRN | C36: Émissions de CO2 (kg par $ US de 2010 de PIB) | D36: EN.ATM.CO2E.KD.GD | AI36: 0.35847882 | AJ36: 0.36078487 | AK36: 0.36483946 | AL36: 0.39849786 | AM36: 0.41949117 | AN36: 0.43310154 | AO36: 0.44171002 | AP36: 0.48526789 | AQ36: 0.42193701 | AR36: 0.40174609 | AS36: 0.41571989 | AT36: 0.4038366 | AU36: 0.38145903 | AV36: 0.44253676 | AW36: 0.40738526 | AX36: 0.39692983 | AY36: 0.57289245 | AZ36: 0.54328917 | BA36: 0.61370379 | BB36: 0.62171126 | BC36: 0.55182504 | BD36: 0.54391271 | BE36: 0.53655218 | BF36: 0.54139547 | BG36: 0.54542607 | BH36: 0.4947839 | BI36: 0.55262181 | BJ36: 0.57055315 | BK36: 0.58979516 | BL36: 0.53151166 | BM36: 0.71396368
A37: Bhoutan | B37: BTN | C37: Émissions de CO2 (kg par $ US de 2010 de PIB) | D37: EN.ATM.CO2E.KD.GD | AI37: 0.44427351 | AJ37: 0.43986085 | AK37: 0.47183545 | AL37: 0.39935355 | AM37: 0.44251632 | AN37: 0.49382891 | AO37: 0.56387177 | AP37: 0.68778657 | AQ37: 0.64299322 | AR37: 0.5972037 | AS37: 0.59355551 | AT37: 0.53439203 | AU37: 0.52235271 | AV37: 0.44467402 | AW37: 0.34815288 | AX37: 0.4092881 | AY37: 0.38452528 | AZ37: 0.32586432 | BA37: 0.32958746 | BB37: 0.28991055 | BC37: 0.32185244 | BD37: 0.44976656 | BE37: 0.4794383 | BF37: 0.51120361 | BG37: 0.53885389 | BH37: 0.52011462 | BI37: 0.56701583 | BJ37: 0.57758251 | BK37: 0.61974685 | BL37: 0.57743751 | BM37: 0.46461766
A38: Botswana | B38: BWA | C38: Émissions de CO2 (kg par $ US de 2010 de PIB) | D38: EN.ATM.CO2E.KD.GD | AI38: 0.53227776 | AJ38: 0.48250531 | AK38: 0.56545123 | AL38: 0.54664507 | AM38: 0.49997722 | AN38: 0.48377305 | AO38: 0.41787161 | AP38: 0.40561137 | AQ38: 0.48497885 | AR38: 0.46340105 | AS38: 0.47501256 | AT38: 0.45406787 | AU38: 0.44592568 | AV38: 0.41438669 | AW38: 0.40916859 | AX38: 0.42172467 | AY38: 0.37173788 | AZ38: 0.37140808 | BA38: 0.36578043 | BB38: 0.40604938 | BC38: 0.29695693 | BD38: 0.32012657 | BE38: 0.28194579 | BF38: 0.4029554 | BG38: 0.49146256 | BH38: 0.51362361 | BI38: 0.45701864 | BJ38: 0.48585159 | BK38: 0.51232614 | BL38: 0.44401094 | BM38: 0.38952033
A39: République centrafricaine | B39: CAF | C39: Émissions de CO2 (kg par $ US de 2010 de PIB) | D39: EN.ATM.CO2E.KD.GD | AI39: 0.099143831 | AJ39: 0.095653011 | AK39: 0.10905832 | AL39: 0.11307035 | AM39: 0.10990897 | AN39: 0.10450479 | AO39: 0.11098594 | AP39: 0.10539981 | AQ39: 0.13707762 | AR39: 0.1377838 | AS39: 0.14512036 | AT39: 0.14451588 | AU39: 0.13770775 | AV39: 0.13460935 | AW39: 0.12435721 | AX39: 0.12209383 | AY39: 0.12183798 | AZ39: 0.11821138 | BA39: 0.083488694 | BB39: 0.075450821 | BC39: 0.074941051 | BD39: 0.079906536 | BE39: 0.077237531 | BF39: 0.074260331 | BG39: 0.08022971 | BH39: 0.10873759 | BI39: 0.11619117 | BJ39: 0.11977566 | BK39: 0.11887915 | BL39: 0.11847546 | BM39: 0.11801726
A40: Canada | B40: CAN | C40: Émissions de CO2 (kg par $ US de 2010 de PIB) | D40: EN.ATM.CO2E.KD.GD | AI40: 0.47787723 | AJ40: 0.48087701 | AK40: 0.49170411 | AL40: 0.47412192 | AM40: 0.46955262 | AN40: 0.46909816 | AO40: 0.47536571 | AP40: 0.47077818 | AQ40: 0.46071786 | AR40: 0.44676525 | AS40: 0.4420695 | AT40: 0.42752007 | AU40: 0.42960338 | AV40: 0.43822768 | AW40: 0.4187404 | AX40: 0.41525666 | AY40: 0.39831506 | AZ40: 0.41277595 | BA40: 0.39363665 | BB40: 0.38398566 | BC40: 0.38368324 | BD40: 0.38051703 | BE40: 0.37185633 | BF40: 0.36969108 | BG40: 0.36325639 | BH40: 0.35897465 | BI40: 0.3540938 | BJ40: 0.35064225 | BK40: 0.34812737 | BL40: 0.33360845 | BM40: 0.32081516
A41: Europe centrale et les pays baltes | B41: CEB | C41: Émissions de CO2 (kg par $ US de 2010 de PIB) | D41: EN.ATM.CO2E.KD.GD | AI41: 1.4180944 | AJ41: 1.4528256 | AK41: 1.3757799 | AL41: 1.3159009 | AM41: 1.2322806 | AN41: 1.1710911 | AO41: 1.1561037 | AP41: 1.0953091 | AQ41: 1.0016704 | AR41: 0.92820998 | AS41: 0.8837608 | AT41: 0.87180119 | AU41: 0.82409169 | AV41: 0.82364137 | AW41: 0.77701016 | AX41: 0.73984232 | AY41: 0.71136834 | AZ41: 0.67320779 | BA41: 0.63193166 | BB41: 0.60574648 | BC41: 0.61778763 | BD41: 0.59773109 | BE41: 0.57013968 | BF41: 0.54439264 | BG41: 0.51104066 | BH41: 0.49847019 | BI41: 0.49415823 | BJ41: 0.48973099 | BK41: 0.46283037 | BL41: 0.4225786 | BM41: 0.40685477
...

Sheet Feuil11
A1: Last Updated Date | B1: 45343 | C1: 2020 | D1: 2020 | E1: 2015 | F1: 2020 | G1: 2020 | H1: 2020 | I1: 2015 | J1: 2021 | K1: 2020 | L1: 2022
C2: Terres agricoles (% du territoire) | D2: Émissions de CO2 (kg par $ US de 2010 de PIB) | E2: Superficie des zones urbaines (km2) | F2: Retraits annuels d’eau douce, total (milliards de mètres cubes) | G2: Level of water stress: freshwater withdrawal as a proportion of available freshwater resources | H2: Émissions de CO2 (tonnes métriques par habitant) | I2: Production d’électricité renouvelable (% de la production totale d’électricité) | J2: Accès à l’électricité (% de la population) | K2: Hauteur moyenne des précipitations (mm par an) | L2: PIB par habitant ($ US courants)
A3: Country Name | B3: Country Code
A4: Angola | B4: AGO | C4: =VLOOKUP(Feuil11!B4,Feuil1!B:D,3,FALSE) -> 36.8107804604155 | D4: =VLOOKUP(Feuil11!B4,Feuil2!B:C,2,FALSE) -> 0.24342379 | E4: =VLOOKUP(Feuil11!B4,Feuil3!B:C,2,FALSE) -> 2991.3469865533 | F4: =VLOOKUP(Feuil11!B4,Feuil4!B:C,2,FALSE) -> 0.7057 | G4: =VLOOKUP(Feuil11!B4,Feuil5!B:C,2,FALSE) -> 1.8718833 | H4: =VLOOKUP(Feuil11!B4,Feuil6!B:C,2,FALSE) -> 0.59274297 | I4: =VLOOKUP(Feuil11!B4,Feuil7!B:C,2,FALSE) -> 53.174928 | J4: =VLOOKUP(Feuil11!B4,Feuil8!B:C,2,FALSE) -> 48.223854 | K4: =VLOOKUP(Feuil11!B4,Feuil9!B:C,2,FALSE) -> 1010 | L4: =VLOOKUP(Feuil11!B4,Feuil10!B:C,2,FALSE) -> 3000.4442
A5: Albanie | B5: ALB | C5: =VLOOKUP(Feuil11!B5,Feuil1!B:D,3,FALSE) -> 42.538503649635 | D5: =VLOOKUP(Feuil11!B5,Feuil2!B:C,2,FALSE) -> 0.34955163 | E5: =VLOOKUP(Feuil11!B5,Feuil3!B:C,2,FALSE) -> 827.69395654173 | F5: =VLOOKUP(Feuil11!B5,Feuil4!B:C,2,FALSE) -> 0.786 | G5: =VLOOKUP(Feuil11!B5,Feuil5!B:C,2,FALSE) -> 4.7235577 | H5: =VLOOKUP(Feuil11!B5,Feuil6!B:C,2,FALSE) -> 1.5445501 | I5: =VLOOKUP(Feuil11!B5,Feuil7!B:C,2,FALSE) -> 100 | J5: =VLOOKUP(Feuil11!B5,Feuil8!B:C,2,FALSE) -> 100 | K5: =VLOOKUP(Feuil11!B5,Feuil9!B:C,2,FALSE) -> 1485 | L5: =VLOOKUP(Feuil11!B5,Feuil10!B:C,2,FALSE) -> 6810.114
A6: Émirats arabes unis | B6: ARE | C6: =VLOOKUP(Feuil11!B6,Feuil1!B:D,3,FALSE) -> 5.48859476203886 | D6: =VLOOKUP(Feuil11!B6,Feuil2!B:C,2,FALSE) -> 0.49065424 | E6: =VLOOKUP(Feuil11!B6,Feuil3!B:C,2,FALSE) -> 2263.10504571 | F6: =VLOOKUP(Feuil11!B6,Feuil4!B:C,2,FALSE) -> 2.381 | G6: =VLOOKUP(Feuil11!B6,Feuil5!B:C,2,FALSE) -> 1587.3333 | H6: =VLOOKUP(Feuil11!B6,Feuil6!B:C,2,FALSE) -> 20.252272 | I6: =VLOOKUP(Feuil11!B6,Feuil7!B:C,2,FALSE) -> 0.23240111 | J6: =VLOOKUP(Feuil11!B6,Feuil8!B:C,2,FALSE) -> 100 | K6: =VLOOKUP(Feuil11!B6,Feuil9!B:C,2,FALSE) -> 78 | L6: =VLOOKUP(Feuil11!B6,Feuil10!B:C,2,FALSE) -> 53707.98
A7: Argentine | B7: ARG | C7: =VLOOKUP(Feuil11!B7,Feuil1!B:D,3,FALSE) -> 43.0292651706989 | D7: =VLOOKUP(Feuil11!B7,Feuil2!B:C,2,FALSE) -> 0.30014294 | E7: =VLOOKUP(Feuil11!B7,Feuil3!B:C,2,FALSE) -> 11432.7305610191 | F7: =VLOOKUP(Feuil11!B7,Feuil4!B:C,2,FALSE) -> 37.69 | G7: =VLOOKUP(Feuil11!B7,Feuil5!B:C,2,FALSE) -> 10.456664 | H7: =VLOOKUP(Feuil11!B7,Feuil6!B:C,2,FALSE) -> 3.4056175 | I7: =VLOOKUP(Feuil11!B7,Feuil7!B:C,2,FALSE) -> 28.140069 | J7: =VLOOKUP(Feuil11!B7,Feuil8!B:C,2,FALSE) -> 100 | K7: =VLOOKUP(Feuil11!B7,Feuil9!B:C,2,FALSE) -> 591 | L7: =VLOOKUP(Feuil11!B7,Feuil10!B:C,2,FALSE) -> 13650.605
A8: Arménie | B8: ARM | C8: =VLOOKUP(Feuil11!B8,Feuil1!B:D,3,FALSE) -> 58.8689848963822 | D8: =VLOOKUP(Feuil11!B8,Feuil2!B:C,2,FALSE) -> 0.56499286 | E8: =VLOOKUP(Feuil11!B8,Feuil3!B:C,2,FALSE) -> 922.33502653 | F8: =VLOOKUP(Feuil11!B8,Feuil4!B:C,2,FALSE) -> 2.83 | G8: =VLOOKUP(Feuil11!B8,Feuil5!B:C,2,FALSE) -> 57.090982 | H8: =VLOOKUP(Feuil11!B8,Feuil6!B:C,2,FALSE) -> 2.4046838 | I8: =VLOOKUP(Feuil11!B8,Feuil7!B:C,2,FALSE) -> 28.336966 | J8: =VLOOKUP(Feuil11!B8,Feuil8!B:C,2,FALSE) -> 100 | K8: =VLOOKUP(Feuil11!B8,Feuil9!B:C,2,FALSE) -> 562 | L8: =VLOOKUP(Feuil11!B8,Feuil10!B:C,2,FALSE) -> 7018.0515
A9: Australie | B9: AUS | C9: =VLOOKUP(Feuil11!B9,Feuil1!B:D,3,FALSE) -> 46.2524798427461 | D9: =VLOOKUP(Feuil11!B9,Feuil2!B:C,2,FALSE) -> 0.25439944 | E9: =VLOOKUP(Feuil11!B9,Feuil3!B:C,2,FALSE) -> 11945.986036946 | F9: =VLOOKUP(Feuil11!B9,Feuil4!B:C,2,FALSE) -> 8.64 | G9: =VLOOKUP(Feuil11!B9,Feuil5!B:C,2,FALSE) -> 3.4740651 | H9: =VLOOKUP(Feuil11!B9,Feuil6!B:C,2,FALSE) -> 14.776137 | I9: =VLOOKUP(Feuil11!B9,Feuil7!B:C,2,FALSE) -> 13.637841 | J9: =VLOOKUP(Feuil11!B9,Feuil8!B:C,2,FALSE) -> 100 | K9: =VLOOKUP(Feuil11!B9,Feuil9!B:C,2,FALSE) -> 534 | L9: =VLOOKUP(Feuil11!B9,Feuil10!B:C,2,FALSE) -> 65099.846
A10: Autriche | B10: AUT | C10: =VLOOKUP(Feuil11!B10,Feuil1!B:D,3,FALSE) -> 31.5398133785749 | D10: =VLOOKUP(Feuil11!B10,Feuil2!B:C,2,FALSE) -> 0.15302349 | E10: =VLOOKUP(Feuil11!B10,Feuil3!B:C,2,FALSE) -> 2973.712010219 | F10: =VLOOKUP(Feuil11!B10,Feuil4!B:C,2,FALSE) -> 3.49 | G10: =VLOOKUP(Feuil11!B10,Feuil5!B:C,2,FALSE) -> 9.6435479 | H10: =VLOOKUP(Feuil11!B10,Feuil6!B:C,2,FALSE) -> 6.6326457 | I10: =VLOOKUP(Feuil11!B10,Feuil7!B:C,2,FALSE) -> 76.490779 | J10: =VLOOKUP(Feuil11!B10,Feuil8!B:C,2,FALSE) -> 100 | K10: =VLOOKUP(Feuil11!B10,Feuil9!B:C,2,FALSE) -> 1110 | L10: =VLOOKUP(Feuil11!B10,Feuil10!B:C,2,FALSE) -> 52084.681
A11: Azerbaïdjan | B11: AZE | C11: =VLOOKUP(Feuil11!B11,Feuil1!B:D,3,FALSE) -> 57.8382498850519 | D11: =VLOOKUP(Feuil11!B11,Feuil2!B:C,2,FALSE) -> 0.6685963 | E11: =VLOOKUP(Feuil11!B11,Feuil3!B:C,2,FALSE) -> 2589.858867181 | F11: =VLOOKUP(Feuil11!B11,Feuil4!B:C,2,FALSE) -> 12.59 | G11: =VLOOKUP(Feuil11!B11,Feuil5!B:C,2,FALSE) -> 55.597262 | H11: =VLOOKUP(Feuil11!B11,Feuil6!B:C,2,FALSE) -> 3.3988496 | I11: =VLOOKUP(Feuil11!B11,Feuil7!B:C,2,FALSE) -> 7.0398574 | J11: =VLOOKUP(Feuil11!B11,Feuil8!B:C,2,FALSE) -> 100 | K11: =VLOOKUP(Feuil11!B11,Feuil9!B:C,2,FALSE) -> 447 | L11: =VLOOKUP(Feuil11!B11,Feuil10!B:C,2,FALSE) -> 7762.0738
A12: Burundi | B12: BDI | C12: =VLOOKUP(Feuil11!B12,Feuil1!B:D,3,FALSE) -> 80.8411214953271 | D12: =VLOOKUP(Feuil11!B12,Feuil2!B:C,2,FALSE) -> 0.22168819 | E12: =VLOOKUP(Feuil11!B12,Feuil3!B:C,2,FALSE) -> 887.842343383 | F12: =VLOOKUP(Feuil11!B12,Feuil4!B:C,2,FALSE) -> 0.2801 | G12: =VLOOKUP(Feuil11!B12,Feuil5!B:C,2,FALSE) -> 10.192868 | H12: =VLOOKUP(Feuil11!B12,Feuil6!B:C,2,FALSE) -> 0.058384022 | I12: =VLOOKUP(Feuil11!B12,Feuil7!B:C,2,FALSE) -> 82.709385 | J12: =VLOOKUP(Feuil11!B12,Feuil8!B:C,2,FALSE) -> 10.233828 | K12: =VLOOKUP(Feuil11!B12,Feuil9!B:C,2,FALSE) -> 1274 | L12: =VLOOKUP(Feuil11!B12,Feuil10!B:C,2,FALSE) -> 259.02503
A13: Belgique | B13: BEL | C13: =VLOOKUP(Feuil11!B13,Feuil1!B:D,3,FALSE) -> 45.066357331572 | D13: =VLOOKUP(Feuil11!B13,Feuil2!B:C,2,FALSE) -> 0.18197096 | E13: =VLOOKUP(Feuil11!B13,Feuil3!B:C,2,FALSE) -> 7730.879239745 | F13: =VLOOKUP(Feuil11!B13,Feuil4!B:C,2,FALSE) -> 4.199 | G13: =VLOOKUP(Feuil11!B13,Feuil5!B:C,2,FALSE) -> 51.584767 | H13: =VLOOKUP(Feuil11!B13,Feuil6!B:C,2,FALSE) -> 7.3981307 | I13: =VLOOKUP(Feuil11!B13,Feuil7!B:C,2,FALSE) -> 20.800023 | J13: =VLOOKUP(Feuil11!B13,Feuil8!B:C,2,FALSE) -> 100 | K13: =VLOOKUP(Feuil11!B13,Feuil9!B:C,2,FALSE) -> 847 | L13: =VLOOKUP(Feuil11!B13,Feuil10!B:C,2,FALSE) -> 49926.825
A14: Bénin | B14: BEN | C14: =VLOOKUP(Feuil11!B14,Feuil1!B:D,3,FALSE) -> 35.0301525363604 | D14: =VLOOKUP(Feuil11!B14,Feuil2!B:C,2,FALSE) -> 0.54194209 | E14: =VLOOKUP(Feuil11!B14,Feuil3!B:C,2,FALSE) -> 2005.9093441513 | F14: =VLOOKUP(Feuil11!B14,Feuil4!B:C,2,FALSE) -> 0.13 | G14: =VLOOKUP(Feuil11!B14,Feuil5!B:C,2,FALSE) -> 0.97524381 | H14: =VLOOKUP(Feuil11!B14,Feuil6!B:C,2,FALSE) -> 0.63120481 | I14: =VLOOKUP(Feuil11!B14,Feuil7!B:C,2,FALSE) -> 5.5555556 | J14: =VLOOKUP(Feuil11!B14,Feuil8!B:C,2,FALSE) -> 41.973633 | K14: =VLOOKUP(Feuil11!B14,Feuil9!B:C,2,FALSE) -> 1039 | L14: =VLOOKUP(Feuil11!B14,Feuil10!B:C,2,FALSE) -> 1302.851
A15: Burkina Faso | B15: BFA | C15: =VLOOKUP(Feuil11!B15,Feuil1!B:D,3,FALSE) -> 46.1038011695906 | D15: =VLOOKUP(Feuil11!B15,Feuil2!B:C,2,FALSE) -> 0.35756353 | E15: =VLOOKUP(Feuil11!B15,Feuil3!B:C,2,FALSE) -> 1599.295141703 | F15: =VLOOKUP(Feuil11!B15,Feuil4!B:C,2,FALSE) -> 0.818 | G15: =VLOOKUP(Feuil11!B15,Feuil5!B:C,2,FALSE) -> 7.8202677 | H15: =VLOOKUP(Feuil11!B15,Feuil6!B:C,2,FALSE) -> 0.25353319 | I15: =VLOOKUP(Feuil11!B15,Feuil7!B:C,2,FALSE) -> 9.3540387 | J15: =VLOOKUP(Feuil11!B15,Feuil8!B:C,2,FALSE) -> 18.950687 | K15: =VLOOKUP(Feuil11!B15,Feuil9!B:C,2,FALSE) -> 748 | L15: =VLOOKUP(Feuil11!B15,Feuil10!B:C,2,FALSE) -> 830.03715
... A157: Zimbabwe | B157: ZWE | C157: =VLOOKUP(Feuil11!B157,Feuil1!B:D,3,FALSE) -> 41.8766963939511 | D157: =VLOOKUP(Feuil11!B157,Feuil2!B:C,2,FALSE) -> 0.43728966 | E157: =VLOOKUP(Feuil11!B157,Feuil3!B:C,2,FALSE) -> 2024.485896677 | F157: =VLOOKUP(Feuil11!B157,Feuil4!B:C,2,FALSE) -> 3.7713817 | G157: =VLOOKUP(Feuil11!B157,Feuil5!B:C,2,FALSE) -> 35.405385 | H157: =VLOOKUP(Feuil11!B157,Feuil6!B:C,2,FALSE) -> 0.53048355 | I157: =VLOOKUP(Feuil11!B157,Feuil7!B:C,2,FALSE) -> 52.724276 | J157: =VLOOKUP(Feuil11!B157,Feuil8!B:C,2,FALSE) -> 48.979927 | K157: =VLOOKUP(Feuil11!B157,Feuil9!B:C,2,FALSE) -> 657 | L157: =VLOOKUP(Feuil11!B157,Feuil10!B:C,2,FALSE) -> 1676.8215

Sheet Feuil1
A1: Data Source | B1: Indicateurs du développement dans le monde
A3: Last Updated Date | B3: 45343 | C3: Terres agricoles (% du territoire) | D3: Terres agricoles (% du territoire)
A5: Country Name | B5: Country Code | C5: 2021 | D5: 2020
A6: Aruba | B6: ABW | C6: 11.1111111111111 | D6: 11.1111111111111
B7: AFE | C7: 46.485779313587 | D7: 46.467607648862
A8: Afghanistan | B8: AFG | C8: 58.7415482268525 | D8: 58.7415482268525
B9: AFW | C9: 40.2593615824761 | D9: 40.1720279737287
A10: Angola | B10: AGO | C10: 36.8147910483677 | D10: 36.8107804604155
A11: Albanie | B11: ALB | C11: 41.471897810219 | D11: 42.538503649635
A12: Andorre | B12: AND | C12: 39.9068085106383 | D12: 39.9517021276596
A13: Le monde arabe | B13: ARB | C13: 39.9707423553453 | D13: 39.9732904781319
A14: Émirats arabes unis | B14: ARE | C14: 5.51339763446916 | D14: 5.48859476203886
A15: Argentine | B15: ARG | C15: 43.1023461553921 | D15: 43.0292651706989
A16: Arménie | B16: ARM | C16: 58.8275377590446 | D16: 58.8689848963822
A17: Samoa américaines | B17: ASM | C17: 14.5 | D17: 14.35
A18: Antigua-et-Barbuda | B18: ATG | C18: 20.4545454545455 | D18: 20.4545454545455
A19: Australie | B19: AUS | C19: 47.2592374954823 | D19: 46.2524798427461
A20: Autriche | B20: AUT | C20: 31.4767256422685 | D20: 31.5398133785749
A21: Azerbaïdjan | B21: AZE | C21: 57.8415003024803 | D21: 57.8382498850519
... A56: Cuba | B56: CUB | C56: 61.6666666666667 | D56: 61.6666666666667
A57: Curacao | B57: CUW
A58: Îles Caïmans | B58: CYM | C58: 11.25 | D58: 11.25
A59: Chypre | B59: CYP | C59: 13.3262878787879 | D59: 13.8148593073593
A60: République tchèque | B60: CZE | C60: 45.730560511424 | D60: 45.6468665918898
A61: Allemagne | B61: DEU | C61: 47.4856177910072 | D61: 47.4970663155786
A62: Djibouti | B62: DJI | C62: 73.5073339085419 | D62: 73.5073339085419
A63: Dominique | B63: DMA | C63: 33.3333333333333 | D63: 33.3333333333333
A64: Danemark | B64: DNK | C64: 65.45 | D64: 65.499675
A65: République dominicaine | B65: DOM | C65: 51.1034903536639 | D65: 51.1034903536639
A66: Algérie | B66: DZA | C66: 17.347004145287 | D66: 17.347004145287
A67: Asie de l’Est et Pacifique (hors revenu élevé) | B67: EAP | C67: 48.8253826297474 | D67: 48.836245873214
A68: de dividende précoce démographique | B68: EAR | C68: 40.0540617351243 | D68: 40.0236948717885
A69: Asie de l’Est et Pacifique | B69: EAS | C69: 47.4708511530475 | D69: 47.1615817378497
... A89: Ghana | B89: GHA | C89: 55.393019913595 | D89: 55.393019913595
A90: Gibraltar | B90: GIB
A91: Guinée | B91: GIN | C91: 59.5718704216181 | D91: 59.5596614032232
A92: Gambie | B92: GMB | C92: 62.6482213438735 | D92: 62.6482213438735
A93: Guinée-Bissau | B93: GNB | C93: 28.9868421052632 | D93: 28.9868421052632
A94: Guinée équatoriale | B94: GNQ | C94: 3.74046345811052 | D94: 3.74046345811052
A95: Grèce | B95: GRC | C95: 45.5173622963538 | D95: 45.5173622963538
...

Sheet Feuil2
A1: Data Source | B1: Indicateurs du développement dans le monde
A2: Last Updated Date | B2: 45343
C3: Émissions de CO2 (kg par $ US de 2010 de PIB)
A4: Country Name | B4: Country Code | C4: 2020
A5: Aruba | B5: ABW
B6: AFE | C6: 0.54829262
A7: Afghanistan | B7: AFG | C7: 0.42233964
B8: AFW | C8: 0.26063217
A9: Angola | B9: AGO | C9: 0.24342379
A10: Albanie | B10: ALB | C10: 0.34955163
A11: Andorre | B11: AND | C11: 0.16796754
A12: Le monde arabe | B12: ARB | C12: 0.66731218
A13: Émirats arabes unis | B13: ARE | C13: 0.49065424
A14: Argentine | B14: ARG | C14: 0.30014294
A15: Arménie | B15: ARM | C15: 0.56499286
A16: Samoa américaines | B16: ASM
A17: Antigua-et-Barbuda | B17: ATG | C17: 0.34597473
A18: Australie | B18: AUS | C18: 0.25439944
A19: Autriche | B19: AUT | C19: 0.15302349
A20: Azerbaïdjan | B20: AZE | C20: 0.6685963
A21: Burundi | B21: BDI | C21: 0.22168819
A22: Belgique | B22: BEL | C22: 0.18197096
A23: Bénin | B23: BEN | C23: 0.54194209
A24: Burkina Faso | B24: BFA | C24: 0.35756353
A25: Bangladesh | B25: BGD | C25: 0.32048727
A26: Bulgarie | B26: BGR | C26: 0.61859373
A27: Bahreïn | B27: BHR | C27: 0.97331837
A28: Bahamas | B28: BHS | C28: 0.26465695
... A31: Belize | B31: BLZ | C31: 0.35117536
A32: Bermudes | B32: BMU
A33: Bolivie | B33: BOL | C33: 0.52717829
A34: Brésil | B34: BRA | C34: 0.23529857
A35: Barbade | B35: BRB | C35: 0.25915961
A36: Brunéi Darussalam | B36: BRN | C36: 0.71396368
A37: Bhoutan | B37: BTN | C37: 0.46461766
A38: Botswana | B38: BWA | C38: 0.38952033
A39: République centrafricaine | B39: CAF | C39: 0.11801726
A40: Canada | B40: CAN | C40: 0.32081516
A41: Europe centrale et les pays baltes | B41: CEB | C41: 0.40685477
A42: Suisse | B42: CHE | C42: 0.047757744
...

Sheet Feuil3
A1: Data Source | B1: Indicateurs du développement dans le monde
A3: Last Updated Date | B3: 45343
C4: Superficie des zones urbaines (km2)
A5: Country Name | B5: Country Code | C5: 2015
A6: Aruba | B6: ABW | C6: 97.34080781558
B7: AFE | C7: 63984.1243767853
A8: Afghanistan | B8: AFG | C8: 3993.83610705
B9: AFW | C9: 51046.987690028
A10: Angola | B10: AGO | C10: 2991.3469865533
A11: Albanie | B11: ALB | C11: 827.69395654173
A12: Andorre | B12: AND | C12: 30.9358154312
A13: Le monde arabe | B13: ARB | C13: 76974.6325607486
A14: Émirats arabes unis | B14: ARE | C14: 2263.10504571
A15: Argentine | B15: ARG | C15: 11432.7305610191
A16: Arménie | B16: ARM | C16: 922.33502653
A17: Samoa américaines | B17: ASM | C17: 23.43530367779
A18: Antigua-et-Barbuda | B18: ATG | C18: 31.86330246835
A19: Australie | B19: AUS | C19: 11945.986036946
A20: Autriche | B20: AUT | C20: 2973.712010219
A21: Azerbaïdjan | B21: AZE | C21: 2589.858867181
... A43: Suisse | B43: CHE | C43: 4016.815073034
A44: Îles Anglo-Normandes | B44: CHI
A45: Chili | B45: CHL | C45: 3579.6703573598
A46: Chine | B46: CHN | C46: 522345.1853048
A47: Côte d'Ivoire | B47: CIV | C47: 2981.9568951999
A48: Cameroun | B48: CMR | C48: 2352.11104215641
A49: Congo | B49: République démocratique du
A50: Congo | B50: République du
A51: Colombie | B51: COL | C51: 5114.5584541567
A52: Comores | B52: COM | C52: 142.53415404781
A53: Cabo Verde | B53: CPV | C53: 59.554326767999
A54: Costa Rica | B54: CRI | C54: 1475.94358331317
A55: Petits états des Caraïbes | B55: CSS | C55: 3051.10718091291
A56: Cuba | B56: CUB | C56: 3053.18468179
A57: Curacao | B57: CUW | C57: 118.118928362573
A58: Îles Caïmans | B58: CYM | C58: 43.96772397219
A59: Chypre | B59: CYP | C59: 518.98037655244
A60: République tchèque | B60: CZE | C60: 4023.3993128
A61: Allemagne | B61: DEU | C61: 36996.443574016
A62: Djibouti | B62: DJI | C62: 51.25016233939
...

Sheet Feuil4
A1: Data Source | B1: Indicateurs du développement dans le monde
A2: Last Updated Date | B2: 45343
C3: Retraits annuels d’eau douce, total (milliards de mètres cubes)
A4: Country Name | B4: Country Code | C4: 2020
A5: Aruba | B5: ABW
B6: AFE | C6: 98.377503
A7: Afghanistan | B7: AFG | C7: 20.282
B8: AFW | C8: 32.228108
A9: Angola | B9: AGO | C9: 0.7057
A10: Albanie | B10: ALB | C10: 0.786
A11: Andorre | B11: AND
A12: Le monde arabe | B12: ARB | C12: 244.88904
A13: Émirats arabes unis | B13: ARE | C13: 2.381
A14: Argentine | B14: ARG | C14: 37.69
A15: Arménie | B15: ARM | C15: 2.83
A16: Samoa américaines | B16: ASM
A17: Antigua-et-Barbuda | B17: ATG | C17: 0.0044
A18: Australie | B18: AUS | C18: 8.64
A19: Autriche | B19: AUT | C19: 3.49
A20: Azerbaïdjan | B20: AZE | C20: 12.59
A21: Burundi | B21: BDI | C21: 0.2801
A22: Belgique | B22: BEL | C22: 4.199
A23: Bénin | B23: BEN | C23: 0.13
A24: Burkina Faso | B24: BFA | C24: 0.818
A25: Bangladesh | B25: BGD | C25: 35.87
A26: Bulgarie | B26: BGR | C26: 5.076
A27: Bahreïn | B27: BHR | C27: 0.1551
A28: Bahamas | B28: BHS
A29: Bosnie-Herzégovine | B29: BIH | C29: 0.30128
A30: Bélarus | B30: BLR | C30: 1.328
A31: Belize | B31: BLZ | C31: 0.101
A32: Bermudes | B32: BMU
A33: Bolivie | B33: BOL | C33: 2.088
A34: Brésil | B34: BRA | C34: 67.19
A35: Barbade | B35: BRB | C35: 0.07
A36: Brunéi Darussalam | B36: BRN | C36: 0.092
A37: Bhoutan | B37: BTN | C37: 0.3379
A38: Botswana | B38: BWA | C38: 0.2204276
A39: République centrafricaine | B39: CAF | C39: 0.0725
A40: Canada | B40: CAN | C40: 36.253
...

Sheet Feuil5
A1: Data Source | B1: Indicateurs du développement dans le monde
A2: Last Updated Date | B2: 45343 | C2: Niveau de stress hydrique
C3: Level of water stress: freshwater withdrawal as a proportion of available freshwater resources
A4: Country Name | B4: Country Code | C4: 2020
A5: Aruba | B5: ABW
B6: AFE
A7: Afghanistan | B7: AFG | C7: 54.757019
B8: AFW
A9: Angola | B9: AGO | C9: 1.8718833
A10: Albanie | B10: ALB | C10: 4.7235577
A11: Andorre | B11: AND
A12: Le monde arabe | B12: ARB
A13: Émirats arabes unis | B13: ARE | C13: 1587.3333
A14: Argentine | B14: ARG | C14: 10.456664
A15: Arménie | B15: ARM | C15: 57.090982
A16: Samoa américaines | B16: ASM
A17: Antigua-et-Barbuda | B17: ATG | C17: 8.4615385
A18: Australie | B18: AUS | C18: 3.4740651
A19: Autriche | B19: AUT | C19: 9.6435479
A20: Azerbaïdjan | B20: AZE | C20: 55.597262
A21: Burundi | B21: BDI | C21: 10.192868
A22: Belgique | B22: BEL | C22: 51.584767
A23: Bénin | B23: BEN | C23: 0.97524381
A24: Burkina Faso | B24: BFA | C24: 7.8202677
A25: Bangladesh | B25: BGD | C25: 5.7233395
A26: Bulgarie | B26: BGR | C26: 37.519403
A27: Bahreïn | B27: BHR | C27: 133.7069
A28: Bahamas | B28: BHS
A29: Bosnie-Herzégovine | B29: BIH | C29: 2.0005312
A30: Bélarus | B30: BLR | C30: 4.37706
A31: Belize | B31: BLZ | C31: 1.2602945
A32: Bermudes | B32: BMU
A33: Bolivie | B33: BOL | C33: 1.1770011
A34: Brésil | B34: BRA | C34: 1.4793043
A35: Barbade | B35: BRB | C35: 87.5
A36: Brunéi Darussalam | B36: BRN | C36: 3.4664657
A37: Bhoutan | B37: BTN | C37: 1.4138075
A38: Botswana | B38: BWA | C38: 2.3050047
A39: République centrafricaine | B39: CAF | C39: 0.33564815
A40: Canada | B40: CAN | C40: 3.7335736
...

Sheet Feuil6
A1: Data Source | B1: Indicateurs du développement dans le monde
A2: Last Updated Date | B2: 45343
C3: Émissions de CO2 (tonnes métriques par habitant)
A4: Country Name | B4: Country Code | C4: 2020
A5: Aruba | B5: ABW
B6: AFE | C6: 0.79541991
A7: Afghanistan | B7: AFG | C7: 0.22347887
B8: AFW | C8: 0.46315027
A9: Angola | B9: AGO | C9: 0.59274297
A10: Albanie | B10: ALB | C10: 1.5445501
A11: Andorre | B11: AND | C11: 5.777148
A12: Le monde arabe | B12: ARB | C12: 3.9290777
A13: Émirats arabes unis | B13: ARE | C13: 20.252272
A14: Argentine | B14: ARG | C14: 3.4056175
A15: Arménie | B15: ARM | C15: 2.4046838
A16: Samoa américaines | B16: ASM
A17: Antigua-et-Barbuda | B17: ATG | C17: 5.1217301
A18: Australie | B18: AUS | C18: 14.776137
A19: Autriche | B19: AUT | C19: 6.6326457
A20: Azerbaïdjan | B20: AZE | C20: 3.3988496
A21: Burundi | B21: BDI | C21: 0.058384022
A22: Belgique | B22: BEL | C22: 7.3981307
A23: Bénin | B23: BEN | C23: 0.63120481
A24: Burkina Faso | B24: BFA | C24: 0.25353319
A25: Bangladesh | B25: BGD | C25: 0.51064756
A26: Bulgarie | B26: BGR | C26: 4.9232804
A27: Bahreïn | B27: BHR | C27: 21.976908
A28: Bahamas | B28: BHS | C28: 6.0422515
... A31: Belize | B31: BLZ | C31: 1.7411077
A32: Bermudes | B32: BMU
A33: Bolivie | B33: BOL | C33: 1.5394647
A34: Brésil | B34: BRA | C34: 1.9425234
A35: Barbade | B35: BRB | C35: 3.9048712
A36: Brunéi Darussalam | B36: BRN | C36: 21.705812
A37: Bhoutan | B37: BTN | C37: 1.3400543
A38: Botswana | B38: BWA | C38: 2.2634631
A39: République centrafricaine | B39: CAF | C39: 0.044282073
A40: Canada | B40: CAN | C40: 13.599375
A41: Europe centrale et les pays baltes | B41: CEB | C41: 5.8572058
A42: Suisse | B42: CHE | C42: 4.0420728
...

Sheet Feuil7
A1: Data Source | B1: Indicateurs du développement dans le monde
A2: Last Updated Date | B2: 45343
C3: Production d’électricité renouvelable (% de la production totale d’électricité)
A4: Country Name | B4: Country Code | C4: 2015
A5: Aruba | B5: ABW | C5: 14.856161
B6: AFE | C6: 25.675879
A7: Afghanistan | B7: AFG | C7: 86.050111
B8: AFW | C8: 31.233531
A9: Angola | B9: AGO | C9: 53.174928
A10: Albanie | B10: ALB | C10: 100
A11: Andorre | B11: AND | C11: 86.1167
A12: Le monde arabe | B12: ARB | C12: 2.9207017
A13: Émirats arabes unis | B13: ARE | C13: 0.23240111
A14: Argentine | B14: ARG | C14: 28.140069
A15: Arménie | B15: ARM | C15: 28.336966
A16: Samoa américaines | B16: ASM | C16: 0.88547816
A17: Antigua-et-Barbuda | B17: ATG | C17: 0
A18: Australie | B18: AUS | C18: 13.637841
A19: Autriche | B19: AUT | C19: 76.490779
A20: Azerbaïdjan | B20: AZE | C20: 7.0398574
... A114: Inde | B114: IND | C114: 15.34305
A115: Non classifié | B115: INX
A116: Irlande | B116: IRL | C116: 27.965408
A117: Iran, République islamique d’ | B117: IRN | C117: 5.1048879
A118: Iraq | B118: IRQ | C118: 3.7317547
A119: Islande | B119: ISL | C119: 99.978722
A120: Israël | B120: ISR | C120: 1.8902002
A121: Italie | B121: ITA | C121: 38.679225
A122: Jamaïque | B122: JAM | C122: 10.262009
A123: Jordanie | B123: JOR | C123: 0.967708
A124: Japon | B124: JPN | C124: 15.984781
A125: Kazakhstan | B125: KAZ | C125: 8.8740279
A126: Kenya | B126: KEN | C126: 87.514247
A127: République kirghize | B127: KGZ | C127: 85.188028
... A270: Zimbabwe | B270: ZWE | C270: 52.724276

Sheet Feuil8
A1: Data Source | B1: Indicateurs du développement dans le monde
A2: Last Updated Date | B2: 45343
C3: Accès à l’électricité (% de la population)
A4: Country Name | B4: Country Code | C4: 2021
A5: Aruba | B5: ABW | C5: 100
B6: AFE | C6: 48.103609
A7: Afghanistan | B7: AFG | C7: 97.7
B8: AFW | C8: 54.224187
A9: Angola | B9: AGO | C9: 48.223854
A10: Albanie | B10: ALB | C10: 100
A11: Andorre | B11: AND | C11: 100
A12: Le monde arabe | B12: ARB | C12: 90.845661
A13: Émirats arabes unis | B13: ARE | C13: 100
A14: Argentine | B14: ARG | C14: 100
A15: Arménie | B15: ARM | C15: 100
A16: Samoa américaines | B16: ASM
A17: Antigua-et-Barbuda | B17: ATG | C17: 100
A18: Australie | B18: AUS | C18: 100
A19: Autriche | B19: AUT | C19: 100
A20: Azerbaïdjan | B20: AZE | C20: 100
A21: Burundi | B21: BDI | C21: 10.233828
A22: Belgique | B22: BEL | C22: 100
A23: Bénin | B23: BEN | C23: 41.973633
A24: Burkina Faso | B24: BFA | C24: 18.950687
A25: Bangladesh | B25: BGD | C25: 98.991028
A26: Bulgarie | B26: BGR | C26: 99.8
A27: Bahreïn | B27: BHR | C27: 100
A28: Bahamas | B28: BHS | C28: 100
... A114: Inde | B114: IND | C114: 99.572525
A115: Non classifié | B115: INX
A116: Irlande | B116: IRL | C116: 100
A117: Iran, République islamique d’ | B117: IRN | C117: 100
A118: Iraq | B118: IRQ | C118: 100
A119: Islande | B119: ISL | C119: 100
A120: Israël | B120: ISR | C120: 100
A121: Italie | B121: ITA | C121: 100
A122: Jamaïque | B122: JAM | C122: 100
A123: Jordanie | B123: JOR | C123: 99.9
A124: Japon | B124: JPN | C124: 100
A125: Kazakhstan | B125: KAZ | C125: 100
...

Sheet Feuil9
A1: Data Source | B1: Indicateurs du développement dans le monde
A2: Last Updated Date | B2: 45343
C3: Hauteur moyenne des précipitations (mm par an)
A4: Country Name | B4: Country Code | C4: 2020
A5: Aruba | B5: ABW
B6: AFE
A7: Afghanistan | B7: AFG | C7: 327
B8: AFW
A9: Angola | B9: AGO | C9: 1010
A10: Albanie | B10: ALB | C10: 1485
A11: Andorre | B11: AND
A12: Le monde arabe | B12: ARB
A13: Émirats arabes unis | B13: ARE | C13: 78
A14: Argentine | B14: ARG | C14: 591
A15: Arménie | B15: ARM | C15: 562
A16: Samoa américaines | B16: ASM
A17: Antigua-et-Barbuda | B17: ATG | C17: 1030
A18: Australie | B18: AUS | C18: 534
A19: Autriche | B19: AUT | C19: 1110
A20: Azerbaïdjan | B20: AZE | C20: 447
A21: Burundi | B21: BDI | C21: 1274
A22: Belgique | B22: BEL | C22: 847
A23: Bénin | B23: BEN | C23: 1039
A24: Burkina Faso | B24: BFA | C24: 748
A25: Bangladesh | B25: BGD | C25: 2666
A26: Bulgarie | B26: BGR | C26: 608
A27: Bahreïn | B27: BHR | C27: 83
A28: Bahamas | B28: BHS | C28: 1292
... A31: Belize | B31: BLZ | C31: 1705
A32: Bermudes | B32: BMU
A33: Bolivie | B33: BOL | C33: 1146
A34: Brésil | B34: BRA | C34: 1761
A35: Barbade | B35: BRB | C35: 1422
A36: Brunéi Darussalam | B36: BRN | C36: 2722
A37: Bhoutan | B37: BTN | C37: 2200
A38: Botswana | B38: BWA | C38: 416
A39: République centrafricaine | B39: CAF | C39: 1343
A40: Canada | B40: CAN | C40: 537
A41: Europe centrale et les pays baltes | B41: CEB
A42: Suisse | B42: CHE | C42: 1537
...

Sheet Feuil10
A1: Data Source | B1: Indicateurs du développement dans le monde
A2: Last Updated Date | B2: 45343
C3: PIB par habitant ($ US courants)
A4: Country Name | B4: Country Code | C4: 2022
A5: Aruba | B5: ABW | C5: 33300.839
B6: AFE | C6: 1644.0628
A7: Afghanistan | B7: AFG
B8: AFW | C8: 1785.3122
A9: Angola | B9: AGO | C9: 3000.4442
A10: Albanie | B10: ALB | C10: 6810.114
A11: Andorre | B11: AND | C11: 41992.773
A12: Le monde arabe | B12: ARB | C12: 7625.2525
A13: Émirats arabes unis | B13: ARE | C13: 53707.98
A14: Argentine | B14: ARG | C14: 13650.605
A15: Arménie | B15: ARM | C15: 7018.0515
A16: Samoa américaines | B16: ASM | C16: 19673.39
A17: Antigua-et-Barbuda | B17: ATG | C17: 19919.727
A18: Australie | B18: AUS | C18: 65099.846
A19: Autriche | B19: AUT | C19: 52084.681
A20: Azerbaïdjan | B20: AZE | C20: 7762.0738
... A36: Brunéi Darussalam | B36: BRN | C36: 37152.477
A37: Bhoutan | B37: BTN
A38: Botswana | B38: BWA | C38: 7738.8788
A39: République centrafricaine | B39: CAF | C39: 427.0581
A40: Canada | B40: CAN | C40: 55522.446
A41: Europe centrale et les pays baltes | B41: CEB | C41: 19420.964
A42: Suisse | B42: CHE | C42: 93259.906
A43: Îles Anglo-Normandes | B43: CHI
A44: Chili | B44: CHL | C44: 15355.48
A45: Chine | B45: CHN | C45: 12720.216
A46: Côte d'Ivoire | B46: CIV | C46: 2486.4122
A47: Cameroun | B47: CMR | C47: 1563.4889
A48: Congo, République démocratique du | B48: COD | C48: 653.65622
A49: Congo, République du | B49: COG | C49: 2649.225
A50: Colombie | B50: COL | C50: 6624.1654
A51: Comores | B51: COM | C51: 1484.8925
A52: Cabo Verde | B52: CPV | C52: 3754.3048
A53: Costa Rica | B53: CRI | C53: 13365.356
A54: Petits états des Caraïbes | B54: CSS | C54: 12639.705
A55: Cuba | B55: CUB
...

Sheet Metadata - Countries
A1: Country Name | B1: Country Code | C1: Region | D1: Income_Group
A2: Aruba | B2: ABW | D2: Revenu élevé
B3: AFE | D3: Agrégats
A4: Afghanistan | B4: AFG | C4: Asie du Sud | D4: Faible revenu
B5: AFW | D5: Agrégats
A6: Angola | B6: AGO | C6: Afrique subsaharienne (hors revenu élevé) | D6: Revenu intermédiaire, tranche inférieure
A7: Albanie | B7: ALB | C7: Europe et Asie centrale (hors revenu élevé) | D7: Revenu intermédiaire, tranche supérieure
A8: Andorre | B8: AND | D8: Revenu élevé
A9: Le monde arabe | B9: ARB | D9: Agrégats
A10: Émirats arabes unis | B10: ARE | D10: Revenu élevé
A11: Argentine | B11: ARG | C11: Amérique latine et Caraïbes (hors revenu élevé) | D11: Revenu intermédiaire, tranche supérieure
A12: Arménie | B12: ARM | C12: Europe et Asie centrale (hors revenu élevé) | D12: Revenu intermédiaire, tranche supérieure
A13: Samoa américaines | B13: ASM | D13: Revenu élevé
A14: Antigua-et-Barbuda | B14: ATG | D14: Revenu élevé
A15: Australie | B15: AUS | D15: Revenu élevé
A16: Autriche | B16: AUT | D16: Revenu élevé
A17: Azerbaïdjan | B17: AZE | C17: Europe et Asie centrale (hors revenu élevé) | D17: Revenu intermédiaire, tranche supérieure
A18: Burundi | B18: BDI | C18: Afrique subsaharienne (hors revenu élevé) | D18: Faible revenu
A19: Belgique | B19: BEL | D19: Revenu élevé
A20: Bénin | B20: BEN | C20: Afrique subsaharienne (hors revenu élevé) | D20: Revenu intermédiaire, tranche inférieure
A21: Burkina Faso | B21: BFA | C21: Afrique subsaharienne (hors revenu élevé) | D21: Faible revenu
A22: Bangladesh | B22: BGD | C22: Asie du Sud | D22: Revenu intermédiaire, tranche inférieure
A23: Bulgarie | B23: BGR | C23: Europe et Asie centrale (hors revenu élevé) | D23: Revenu intermédiaire, tranche supérieure
A24: Bahreïn | B24: BHR | D24: Revenu élevé
A25: Bahamas | B25: BHS | D25: Revenu élevé
A26: Bosnie-Herzégovine | B26: BIH | C26: Europe et Asie centrale (hors revenu élevé) | D26: Revenu intermédiaire, tranche supérieure
A27: Bélarus | B27: BLR | C27: Europe et Asie centrale (hors revenu élevé) | D27: Revenu intermédiaire, tranche supérieure
A28: Belize | B28: BLZ | C28: Amérique latine et Caraïbes (hors revenu élevé) | D28: Revenu intermédiaire, tranche supérieure
A29: Bermudes | B29: BMU | D29: Revenu élevé
A30: Bolivie | B30: BOL | C30: Amérique latine et Caraïbes (hors revenu élevé) | D30: Revenu intermédiaire, tranche inférieure
A31: Brésil | B31: BRA | C31: Amérique latine et Caraïbes (hors revenu élevé) | D31: Revenu intermédiaire, tranche supérieure
A32: Barbade | B32: BRB | D32: Revenu élevé
A33: Brunéi Darussalam | B33: BRN | D33: Revenu élevé
A34: Bhoutan | B34: BTN | C34: Asie du Sud | D34: Revenu intermédiaire, tranche inférieure
A35: Botswana | B35: BWA | C35: Afrique subsaharienne (hors revenu élevé) | D35: Revenu intermédiaire, tranche supérieure
A36: République centrafricaine | B36: CAF | C36: Afrique subsaharienne (hors revenu élevé) | D36: Faible revenu
A37: Canada | B37: CAN | D37: Revenu élevé
A38: Europe centrale et les pays baltes | B38: CEB | D38: Agrégats
A39: Suisse | B39: CHE | D39: Revenu élevé
A40: Îles Anglo-Normandes | B40: CHI | D40: Revenu élevé
...

Sheet Metadata - Indicators
A1: INDICATOR_CODE | B1: INDICATOR_NAME | C1: SOURCE_NOTE | D1: SOURCE_ORGANIZATION
